Workbook

Sheet Briefing Note Feed
A1: Feed Description | B1: Feed Values | D1: Feed Tables | E1: (to unlock and modify sheet, password is 123) | AL1: Placeholder page end
A2: Prepared for | D2: Applications Updates
A3: Title | D3: =B9&" Applications Comparison - Point in Time" -> 2025-26 formula placeholder Applications Comparison - Point in Time
A4: Date prepared | D4: Population | E4: Fall 2025 | F4: Fall 2024 | G4: % Change | H4: Winter 2026 | I4: Winter 2025 | J4: % Change
A5: Prepared by | D5: Total Applications
A6: Title | D6: International
A7: Department | D7: Domestic
A8: Date of data extraction
A9: YearA Applications Academic Year Range | B9: 2025-26 formula placeholder
A10: YearA Applications Min Academic Year | B10: 2025 formula placeholder
A11: YearA Applications Min Academic Year+1 | B11: 2026 formula placeholder
A12: YearA Fall 2025 unique applicants
A13: YearA Fall 2025 total applications
A14: YearA Fall 2025 accepted applications
A15: YearA Fall 2025 unique international applicants
A16: YearA Fall 2025 total international applications
A17: YearA Fall 2025 unique domestic applicants
A18: YearA Fall 2025 total domestic applications
A19: YearA Fall 2024 unique applicants
A20: YearA Fall 2024 total applications
A21: YearA Fall 2024 accepted applications
A22: YearA Fall 2024 unique international applicants
A23: YearA Fall 2024 total international applications
... A25: YearA Fall 2024 total domestic applications
A26: YearA Winter 2025 unique applicants | D26: 2026-27 Applications Comparison - Point in Time
A27: YearA Winter 2025 total applications | D27: Population | E27: Fall 2025 | F27: Fall 2024 | G27: % Change | H27: Winter 2026 | I27: Winter 2025 | J27: % Change
A28: YearA Winter 2025 accepted applications | D28: Total Applications
A29: YearA Winter 2025 unique international applicants | D29: International
A30: YearA Winter 2025 total international applications | D30: Domestic
A31: YearA Winter 2025 unique domestic applicants
A32: YearA Winter 2025 total domestic applications | D32: Fall 2025 Applications
A33: YearA Winter 2024 unique applicants
A34: YearA Winter 2024 total applications
A35: YearA Winter 2024 accepted applications
A36: YearA Winter 2024 unique international applicants
A37: YearA Winter 2024 total international applications | D37: Winter 2026 Applications
A38: YearA Winter 2024 unique domestic applicants
A39: YearA Winter 2024 total domestic applications
A40: YearA Applications Academic Year Range
A41: YearA Applications Min Academic Year
...

Sheet FLE Campus
A1: PEOPLE_CODE_ID | B1: BIRTH_DATE | C1: AGE | D1: ACADEMIC_YEAR | E1: ACADEMIC_TERM | F1: ACADEMIC_PERIOD | G1: ACADEMIC_SESSION | H1: DEGREE | I1: DEPARTMENT | J1: CURRICULUM | K1: CREDENTIAL_TYPE | L1: CLASS_LEVEL | M1: FULL_PART | N1: FULL_PART_DISP_WITHDRAWN | O1: FULL_PART_NON_WITHDRAWN | P1: MATCHING | Q1: FLE | R1: ORG_CODE_ID | S1: ORG_NAME_1 | T1: STATUS | U1: CODE_XVAL | V1: LONG_DESC | W1: PROGRAM_START_DATE | X1: PROGRAM_END_DATE | Y1: ENROLL_SEPARATION | Z1: CREDITS | AA1: HERITAGE | AB1: GENDER_IDENTITY | AC1: LEGAL | AD1: CITIZENSHIP

Sheet Budgeted Projections FLE
A1: Programs | B1: Year of Study | C1: Power Campus Program ID | D1: ProgramID & Year of Study | E1: 2025/26 | H1: 2026/27
E2: Domestic FLE | F2: International FLE | G2: Total FLE | H2: Domestic FLE | I2: International FLE | J2: Total FLE
A4: Business Administration Certificate
A5: Accounting | B5: 1 | C5: BAACTC | D5: =C5&B5 -> BAACTC1
A6: Business (Management) | B6: 1 | C6: BABUSC | D6: =C6&B6 -> BABUSC1
A7: Business Administration Diploma
A8: Accounting | B8: 1 | C8: BAACTD | D8: =C8&B8 -> BAACTD1
B9: 2 | C9: BAACTD | D9: =C9&B9 -> BAACTD2
A10: Business (Management) | B10: 1 | C10: BABUSD | D10: =C10&B10 -> BABUSD1
B11: 2 | C11: BABUSD | D11: =C11&B11 -> BABUSD2
A12: Esport (Management) | B12: 1 | C12: BAESPM | D12: =C12&B12 -> BAESPM1
B13: 2 | C13: BAESPM | D13: =C13&B13 -> BAESPM2
A14: Human Resources Management Diploma | B14: 1 | C14: BAHRMD | D14: =C14&B14 -> BAHRMD1
B15: 2 | C15: BAHRMD | D15: =C15&B15 -> BAHRMD2
A16: Global Supply Chain | B16: 1 | C16: GSCMD | D16: =C16&B16 -> GSCMD1
B17: 2 | C17: GSCMD | D17: =C17&B17 -> GSCMD2
A18: Digital Marketing | B18: 1 | C18: DIGMD | D18: =C18&B18 -> DIGMD1
B19: 2 | C19: DIGMD | D19: =C19&B19 -> DIGMD2
A20: Business Administration Diploma Co-op
A21: Accounting | B21: 1 | C21: BAATCO | D21: =C21&B21 -> BAATCO1
B22: 2 | C22: BAATCO | D22: =C22&B22 -> BAATCO2
A23: Business (Management) | B23: 1 | C23: BABSCO | D23: =C23&B23 -> BABSCO1
B24: 2 | C24: BABSCO | D24: =C24&B24 -> BABSCO2
A25: Business Aviation Diploma
A26: Northern Aviation Operations | B26: 1 | C26: NAO | D26: =C26&B26 -> NAO1
B27: 2 | C27: NAO | D27: =C27&B27 -> NAO2
A28: Airline Operations | B28: 1 | C28: ALO | D28: =C28&B28 -> ALO1
B29: 2 | C29: ALO | D29: =C29&B29 -> ALO2
A30: Hospitality and Tourism Management Diploma
A31: Hospitality and Tourism Management Diploma | B31: 1 | C31: HATM | D31: =C31&B31 -> HATM1
B32: 2 | C32: HATM | D32: =C32&B32 -> HATM2
A33: Hospitality Management Diploma | B33: 1 | C33: HOSMNG | D33: =C33&B33 -> HOSMNG1
B34: 2 | C34: HOSMNG | D34: =C34&B34 -> HOSMNG2
A35: Human Resources Management Certificate
A36: Human Resources Management Certificate | B36: 1 | C36: BAHRMC | D36: =C36&B36 -> BAHRMC1
A37: Office Administration Certificate
A38: Office Administration | B38: 1 | C38: OFAC | D38: =C38&B38 -> OFAC1
A39: Executive Admin Professional
A40: Executive Admin Professional | B40: 1 | D40: =C40&B40 -> 1
B41: 2 | D41: =C41&B41 -> 2
...

Sheet Budgeted Projections Total HC
A1: Programs | B1: Year of Study | C1: Power Campus Program ID | D1: ProgramID & Year of Study | E1: 2025/26 | M1: 2026/27
E2: Summer | G2: Fall | I2: Winter | K2: Spring | M2: Summer | O2: Fall | Q2: Winter | S2: Spring
E3: Part-time | F3: Full-time | G3: Part-time | H3: Full-time | I3: Part-time | J3: Full-time | K3: Part-time | L3: Full-time | M3: Part-time | N3: Full-time | O3: Part-time | P3: Full-time | Q3: Part-time | R3: Full-time | S3: Part-time | T3: Full-time
A4: Business Administration Certificate
A5: Accounting | B5: 1 | C5: BAACTC | D5: BAACTC1
A6: Business (Management) | B6: 1 | C6: BABUSC | D6: BABUSC1
A7: Business Administration Diploma
A8: Accounting | B8: 1 | C8: BAACTD | D8: BAACTD1
B9: 2 | C9: BAACTD | D9: BAACTD2
A10: Business (Management) | B10: 1 | C10: BABUSD | D10: BABUSD1
B11: 2 | C11: BABUSD | D11: BABUSD2
A12: Esport (Management) | B12: 1 | C12: BAESPM | D12: BAESPM1
B13: 2 | C13: BAESPM | D13: BAESPM2
A14: Human Resources Management Diploma | B14: 1 | C14: BAHRMD | D14: BAHRMD1
B15: 2 | C15: BAHRMD | D15: BAHRMD2
A16: Global Supply Chain | B16: 1 | C16: GSCMD | D16: GSCMD1
B17: 2 | C17: GSCMD | D17: GSCMD2
A18: Digital Marketing | B18: 1 | C18: DIGMD | D18: DIGMD1
B19: 2 | C19: DIGMD | D19: DIGMD2
A20: Business Administration Diploma Co-op
A21: Accounting | B21: 1 | C21: BAATCO | D21: BAATCO1
B22: 2 | C22: BAATCO | D22: BAATCO2
A23: Business (Management) | B23: 1 | C23: BABSCO | D23: BABSCO1
B24: 2 | C24: BABSCO | D24: BABSCO2
A25: Business Aviation Diploma
A26: Northern Aviation Operations | B26: 1 | C26: NAO | D26: NAO1
B27: 2 | C27: NAO | D27: NAO2
A28: Airline Operations | B28: 1 | C28: ALO | D28: ALO1
B29: 2 | C29: ALO | D29: ALO2
A30: Hospitality and Tourism Management Diploma
A31: Hospitality and Tourism Management Diploma | B31: 1 | C31: HATM | D31: HATM1
B32: 2 | C32: HATM | D32: HATM2
A33: Hospitality Management Diploma | B33: 1 | C33: HOSMNG | D33: HOSMNG1
B34: 2 | C34: HOSMNG | D34: HOSMNG2
A35: Human Resources Management Certificate
A36: Human Resources Management Certificate | B36: 1 | C36: BAHRMC | D36: BAHRMC1
A37: Office Administration Certificate
A38: Office Administration | B38: 1 | C38: OFAC | D38: OFAC1
A39: Executive Admin Professional
A40: Executive Admin Professional | B40: 1 | D40: 1
...

Sheet Budgeted Projections Dom HC
A1: Programs | B1: Year of Study | C1: Power Campus Program ID | D1: ProgramID & Year of Study | E1: 2025/26 | M1: 2026/27
E2: Summer | G2: Fall | I2: Winter | K2: Spring | M2: Summer | O2: Fall | Q2: Winter | S2: Spring
E3: Part-time | F3: Full-time | G3: Part-time | H3: Full-time | I3: Part-time | J3: Full-time | K3: Part-time | L3: Full-time | M3: Part-time | N3: Full-time | O3: Part-time | P3: Full-time | Q3: Part-time | R3: Full-time | S3: Part-time | T3: Full-time
A4: Business Administration Certificate
A5: Accounting | B5: 1 | C5: BAACTC | D5: BAACTC1
A6: Business (Management) | B6: 1 | C6: BABUSC | D6: BABUSC1
A7: Business Administration Diploma
A8: Accounting | B8: 1 | C8: BAACTD | D8: BAACTD1
B9: 2 | C9: BAACTD | D9: BAACTD2
A10: Business (Management) | B10: 1 | C10: BABUSD | D10: BABUSD1
B11: 2 | C11: BABUSD | D11: BABUSD2
A12: Esport (Management) | B12: 1 | C12: BAESPM | D12: BAESPM1
B13: 2 | C13: BAESPM | D13: BAESPM2
A14: Human Resources Management Diploma | B14: 1 | C14: BAHRMD | D14: BAHRMD1
B15: 2 | C15: BAHRMD | D15: BAHRMD2
A16: Global Supply Chain | B16: 1 | C16: GSCMD | D16: GSCMD1
B17: 2 | C17: GSCMD | D17: GSCMD2
A18: Digital Marketing | B18: 1 | C18: DIGMD | D18: DIGMD1
B19: 2 | C19: DIGMD | D19: DIGMD2
A20: Business Administration Diploma Co-op
A21: Accounting | B21: 1 | C21: BAATCO | D21: BAATCO1
B22: 2 | C22: BAATCO | D22: BAATCO2
A23: Business (Management) | B23: 1 | C23: BABSCO | D23: BABSCO1
B24: 2 | C24: BABSCO | D24: BABSCO2
A25: Business Aviation Diploma
A26: Northern Aviation Operations | B26: 1 | C26: NAO | D26: NAO1
B27: 2 | C27: NAO | D27: NAO2
A28: Airline Operations | B28: 1 | C28: ALO | D28: ALO1
B29: 2 | C29: ALO | D29: ALO2
A30: Hospitality and Tourism Management Diploma
A31: Hospitality and Tourism Management Diploma | B31: 1 | C31: HATM | D31: HATM1
B32: 2 | C32: HATM | D32: HATM2
A33: Hospitality Management Diploma | B33: 1 | C33: HOSMNG | D33: HOSMNG1
B34: 2 | C34: HOSMNG | D34: HOSMNG2
A35: Human Resources Management Certificate
A36: Human Resources Management Certificate | B36: 1 | C36: BAHRMC | D36: BAHRMC1
A37: Office Administration Certificate
A38: Office Administration | B38: 1 | C38: OFAC | D38: OFAC1
A39: Executive Admin Professional
A40: Executive Admin Professional | B40: 1 | D40: 1
...

Sheet Budgeted Projections Intl HC
A1: Programs | B1: Year of Study | C1: Power Campus Program ID | D1: ProgramID & Year of Study | E1: 2025/26 | M1: 2025/26
E2: Summer | G2: Fall | I2: Winter | K2: Spring | M2: Summer | O2: Fall | Q2: Winter | S2: Spring
E3: Part-time | F3: Full-time | G3: Part-time | H3: Full-time | I3: Part-time | J3: Full-time | K3: Part-time | L3: Full-time | M3: Part-time | N3: Full-time | O3: Part-time | P3: Full-time | Q3: Part-time | R3: Full-time | S3: Part-time | T3: Full-time
A4: 2026/27
A5: Accounting | B5: 1 | C5: BAACTC | D5: BAACTC1
A6: Business (Management) | B6: 1 | C6: BABUSC | D6: BABUSC1
A7: Business Administration Diploma
A8: Accounting | B8: 1 | C8: BAACTD | D8: BAACTD1
B9: 2 | C9: BAACTD | D9: BAACTD2
A10: Business (Management) | B10: 1 | C10: BABUSD | D10: BABUSD1
B11: 2 | C11: BABUSD | D11: BABUSD2
A12: Esport (Management) | B12: 1 | C12: BAESPM | D12: BAESPM1
B13: 2 | C13: BAESPM | D13: BAESPM2
A14: Human Resources Management Diploma | B14: 1 | C14: BAHRMD | D14: BAHRMD1
B15: 2 | C15: BAHRMD | D15: BAHRMD2
A16: Global Supply Chain | B16: 1 | C16: GSCMD | D16: GSCMD1
B17: 2 | C17: GSCMD | D17: GSCMD2
A18: Digital Marketing | B18: 1 | C18: DIGMD | D18: DIGMD1
B19: 2 | C19: DIGMD | D19: DIGMD2
A20: Business Administration Diploma Co-op
A21: Accounting | B21: 1 | C21: BAATCO | D21: BAATCO1
B22: 2 | C22: BAATCO | D22: BAATCO2
A23: Business (Management) | B23: 1 | C23: BABSCO | D23: BABSCO1
B24: 2 | C24: BABSCO | D24: BABSCO2
A25: Business Aviation Diploma
A26: Northern Aviation Operations | B26: 1 | C26: NAO | D26: NAO1
B27: 2 | C27: NAO | D27: NAO2
A28: Airline Operations | B28: 1 | C28: ALO | D28: ALO1
B29: 2 | C29: ALO | D29: ALO2
A30: Hospitality and Tourism Management Diploma
A31: Hospitality and Tourism Management Diploma | B31: 1 | C31: HATM | D31: HATM1
B32: 2 | C32: HATM | D32: HATM2
A33: Hospitality Management Diploma | B33: 1 | C33: HOSMNG | D33: HOSMNG1
B34: 2 | C34: HOSMNG | D34: HOSMNG2
A35: Human Resources Management Certificate
A36: Human Resources Management Certificate | B36: 1 | C36: BAHRMC | D36: BAHRMC1
A37: Office Administration Certificate
A38: Office Administration | B38: 1 | C38: OFAC | D38: OFAC1
A39: Executive Admin Professional
A40: Executive Admin Professional | B40: 1 | D40: 1
...

Sheet YearA-AppDetails Current Year

Sheet YearA-AppDetails Current Year-1

Sheet YearB-AppDetails Current Year

Sheet YearB-AppDetails Current Year-1
